<?xml version="1.0"?>
<robot name="robbie">

  <link name="base_link">
    <visual>
      <geometry>
        <box size="0.2 0.2 0.05"/>
      </geometry>
      <material name="blue">
        <color rgba="0 0 1 1"/>
      </material>
    </visual>
  </link>

  <link name="link1">
    <visual>
      <geometry>
        <box size="0.1 0.1 0.5"/>
      </geometry>
      <origin xyz="0 0 0.25"/>
      <material name="green">
        <color rgba="0 1 0 1"/>
      </material>
    </visual>
  </link>

  <joint name="joint1" type="revolute">
    <parent link="base_link"/>
    <child link="link1"/>
    <origin xyz="0 0 0.05"/>
    <axis xyz="0 0 1"/>
    <limit lower="-3.14" upper="3.14" effort="1.0" velocity="1.0"/>
  </joint>

  <link name="link2">
    <visual>
      <geometry>
        <box size="0.1 0.1 0.5"/>
      </geometry>
      <origin xyz="0 0 0.25"/>
      <material name="red">
        <color rgba="1 0 0 1"/>
      </material>
    </visual>
  </link>

  <joint name="joint2" type="revolute">
    <parent link="link1"/>
    <child link="link2"/>
    <origin xyz="0 0 0.5"/>
    <axis xyz="0 1 0"/>
    <limit lower="-3.14" upper="3.14" effort="1.0" velocity="1.0"/>
  </joint>


  <link name="link3">
    <visual>
      <geometry>
        <box size="0.1 0.1 0.5"/>
      </geometry>
      <origin xyz="0 0 0.25"/>
      <material name="yellow">
        <color rgba="1 1 0 1"/>
      </material>
    </visual>
  </link>

  <joint name="joint3" type="revolute">
    <parent link="link2"/>
    <child link="link3"/>
    <origin xyz="0 0 0.5"/>
    <axis xyz="0 1 0"/>
    <limit lower="-3.14" upper="3.14" effort="1.0" velocity="1.0"/>
  </joint>

  <link name="link4">
    <visual>
      <geometry>
        <box size="0.1 0.1 0.5"/>
      </geometry>
      <origin xyz="0 0 0.25"/>
      <material name="purple">
        <color rgba="0.5 0 0.5 1"/>
      </material>
    </visual>
  </link>

  <joint name="joint4" type="revolute">
    <parent link="link3"/>
    <child link="link4"/>
    <origin xyz="0 0 0.5"/>
    <axis xyz="0 1 0"/>
    <limit lower="-3.14" upper="3.14" effort="1.0" velocity="1.0"/>
  </joint>
</robot>
